<?xml version="1.0" ?>
<!-- =================================================================================== -->
<!-- |    This document was autogenerated by xacro from /home/keerthivasan/keerthi/catkin/src/manipulator/mrm_description/urdf/mrm.xacro | -->
<!-- |    EDITING THIS FILE BY HAND IS NOT RECOMMENDED                                 | -->
<!-- =================================================================================== -->
<robot name="mrm">
    <link name="base_link">
        <inertial>
            <origin rpy="0.0 0.0 0.0" xyz="0.0 0.0 0.0" />
            <mass value="1024" />
            <inertia ixx="170.667" ixy="0.0" ixz="0.0" iyy="170.667" iyz="0.0" izz="170.667" />
        </inertial>
        <visual>
            <origin rpy="0.0 0.0 0.0" xyz="0.0 0.0 0.0" />
            <geometry>
                <box size="1.0 1.0 1.0" />
            </geometry>
        </visual>
        <collision>
            <origin rpy="0.0 0.0 0.0" xyz="0.0 0.0 0.0" />
            <geometry>
                <box size="1.0 1.0 1.0" />
            </geometry>
        </collision>
    </link>
    <link name="link_01">
        <inertial>
            <origin rpy="0.0 0.0 0.0" xyz="0.0 0.0 0.2" />
            <mass value="157.633" />
            <inertia ixx="13.235" ixy="0.0" ixz="0.0" iyy="13.235" iyz="0.0" izz="9.655" />
        </inertial>
        <visual>
            <origin rpy="0.0 0.0 0.0" xyz="0.0 0.0 0.2" />
            <geometry>
                <cylinder length="0.4" radius="0.35" />
            </geometry>
        </visual>
        <collision>
            <origin rpy="0.0 0.0 0.0" xyz="0.0 0.0 0.2" />
            <geometry>
                <cylinder length="0.4" radius="0.35" />
            </geometry>
        </collision>
    </link>
    <link name="link_02">
        <inertial>
            <origin rpy="0.0 0.0 0.0" xyz="0.0 0.0 0.4" />
            <mass value="57.906" />
            <inertia ixx="12.679" ixy="0.0" ixz="0.0" iyy="12.679" iyz="0.0" izz="0.651" />
        </inertial>
        <visual>
            <origin rpy="0.0 0.0 0" xyz="0.0 0.0 0.4" />
            <geometry>
                <cylinder length="0.8" radius="0.15" />
            </geometry>
        </visual>
        <collision>
            <origin rpy="0.0 0.0 0.0" xyz="0.0 0.0 0.4" />
            <geometry>
                <cylinder length="0.8" radius="0.15" />
            </geometry>
        </collision>
    </link>
    <link name="link_03">
        <inertial>
            <origin rpy="0.0 0.0 0.0" xyz="0.0 0.0 0.4" />
            <mass value="57.906" />
            <inertia ixx="12.679" ixy="0.0" ixz="0.0" iyy="12.679" iyz="0.0" izz="0.651" />
        </inertial>
        <visual name="">
            <origin rpy="0.0 0.0 0.0" xyz="0.0 0.0 0.4" />
            <geometry>
                <cylinder length="0.8" radius="0.15" />
            </geometry>
        </visual>
        <collision>
            <origin rpy="0.0 0.0 0.0" xyz="0.0 0.0 0.4" />
            <geometry>
                <cylinder length="0.8" radius="0.15" />
            </geometry>
        </collision>
    </link>
    <link name="link_04">
        <inertial>
            <origin rpy="0.0 0.0 0.0" xyz="0.0 0.0 0.4" />
            <mass value="57.906" />
            <inertia ixx="12.679" ixy="0.0" ixz="0.0" iyy="12.679" iyz="0.0" izz="0.651" />
        </inertial>
        <visual name="">
            <origin rpy="0.0 0.0 0.0" xyz="0.0 0.0 0.4" />
            <geometry>
                <cylinder length="0.8" radius="0.15" />
            </geometry>
        </visual>
        <collision>
            <origin rpy="0.0 0.0 0.0" xyz="0.0 0.0 0.4" />
            <geometry>
                <cylinder length="0.8" radius="0.15" />
            </geometry>
        </collision>
    </link>
    <link name="link_05">
        <inertial>
            <origin rpy="0.0 0.0 0.0" xyz="0.0 0.0 0.0" />
            <mass value="18.056" />
            <inertia ixx="0.479" ixy="0.0" ixz="0.0" iyy="0.479" iyz="0.0" izz="0.204" />
        </inertial>
        <visual name="">
            <origin rpy="0.0 0.0 0.0" xyz="0.0 0.0 0.125" />
            <geometry>
                <cylinder length="0.25" radius="0.15" />
            </geometry>
        </visual>
        <collision>
            <origin rpy="0.0 0.0 0.0" xyz="0.0 0.0 0.125" />
            <geometry>
                <cylinder length="0.25" radius="0.15" />
            </geometry>
        </collision>
    </link>
    <joint name="base_link_link_01" type="revolute">
        <parent link="base_link" />
        <child link="link_01" />
        <axis xyz="0 0 1" />
        <limit effort="1000.0" lower="-3.14159" upper="3.14159" velocity="0.5" />
        <origin rpy="0 0 0" xyz="0 0 0.5" />
    </joint>
    <transmission name="trans_base_link_link_01">
        <type>transmission_interface/SimpleTransmission</type>
        <joint name="base_link_link_01">
            <hardwareInterface>hardware_interface/EffortJointInterface</hardwareInterface>
        </joint>
        <actuator name="motor_base_link_link_01">
            <mechanicalReduction>1.0</mechanicalReduction>
            <hardwareInterface>hardware_interface/EffortJointInterface</hardwareInterface>
        </actuator>
    </transmission>
    <joint name="link_01_link_02" type="revolute">
        <parent link="link_01" />
        <child link="link_02" />
        <axis xyz="0 1 0" />
        <limit effort="1000.0" lower="-3.14159" upper="3.14159" velocity="0.5" />
        <origin rpy="0 0 0" xyz="0 0 0.4" />
    </joint>
    <transmission name="trans_link_01_link_02">
        <type>transmission_interface/SimpleTransmission</type>
        <joint name="link_01_link_02">
            <hardwareInterface>hardware_interface/EffortJointInterface</hardwareInterface>
        </joint>
        <actuator name="motor_link_01_link_02">
            <mechanicalReduction>1.0</mechanicalReduction>
            <hardwareInterface>hardware_interface/EffortJointInterface</hardwareInterface>
        </actuator>
    </transmission>
    <joint name="link_02_link_03" type="revolute">
        <parent link="link_02" />
        <child link="link_03" />
        <axis xyz="0 1 0" />
        <limit effort="1000.0" lower="-3.14159" upper="3.14159" velocity="0.5" />
        <origin rpy="0 0 0" xyz="0 0 0.8" />
    </joint>
    <transmission name="trans_link_02_link_03">
        <type>transmission_interface/SimpleTransmission</type>
        <joint name="link_02_link_03">
            <hardwareInterface>hardware_interface/EffortJointInterface</hardwareInterface>
        </joint>
        <actuator name="motor_link_02_link_03">
            <mechanicalReduction>1.0</mechanicalReduction>
            <hardwareInterface>hardware_interface/EffortJointInterface</hardwareInterface>
        </actuator>
    </transmission>
    <joint name="link_03_link_04" type="revolute">
        <parent link="link_03" />
        <child link="link_04" />
        <axis xyz="0 1 0" />
        <limit effort="1000.0" lower="-3.14159" upper="3.14159" velocity="0.5" />
        <origin rpy="0 0 0" xyz="0 0 0.8" />
    </joint>
    <transmission name="trans_link_03_link_04">
        <type>transmission_interface/SimpleTransmission</type>
        <joint name="link_03_link_04">
            <hardwareInterface>hardware_interface/EffortJointInterface</hardwareInterface>
        </joint>
        <actuator name="motor_link_03_link_04">
            <mechanicalReduction>1.0</mechanicalReduction>
            <hardwareInterface>hardware_interface/EffortJointInterface</hardwareInterface>
        </actuator>
    </transmission>
    <joint name="link_04_link_05" type="revolute">
        <parent link="link_04" />
        <child link="link_05" />
        <axis xyz="0 1 0" />
        <limit effort="1000.0" lower="-3.14159" upper="3.14159" velocity="0.5" />
        <origin rpy="0 0 0" xyz="0 0 0.8" />
    </joint>
    <transmission name="trans_link_04_link_05">
        <type>transmission_interface/SimpleTransmission</type>
        <joint name="link_04_link_05">
            <hardwareInterface>hardware_interface/EffortJointInterface</hardwareInterface>
        </joint>
        <actuator name="motor_link_04_link_05">
            <mechanicalReduction>1.0</mechanicalReduction>
            <hardwareInterface>hardware_interface/EffortJointInterface</hardwareInterface>
        </actuator>
    </transmission>
    <gazebo>
        <plugin filename="libgazebo_ros_control.so" name="gazebo_ros_control">
            <robotNamespace>/</robotNamespace>
        </plugin>
    </gazebo>
</robot>

